Workbook
Name NomeViaggio: CONFIG!$B$5
Name DataPartenza: CONFIG!$B$6
Name DataRitorno: CONFIG!$B$7
Name UltimoGiorno: CONFIG!$B$8
Name N_Persone: CONFIG!$B$9
Name Tasso_JPY_EUR: CONFIG!$B$10
Name Budget_Target_Pax: CONFIG!$B$11
Name ListaCategorie: OFFSET(CONFIG!$A$62,0,0,COUNTA(CONFIG!$A$62:$A$140),1)
Name ListaStati: OFFSET(CONFIG!$D$62,0,0,COUNTA(CONFIG!$D$62:$D$140),1)
Name ListaPersone: OFFSET(CONFIG!$B$15,0,0,COUNTA(CONFIG!$B$15:$B$19),1)
Name ListaPartecipa: OFFSET(CONFIG!$F$62,0,0,COUNTA(CONFIG!$F$62:$F$140),1)
Name ListaPriorita: OFFSET(CONFIG!$H$62,0,0,COUNTA(CONFIG!$H$62:$H$140),1)
Name ListaValute: OFFSET(CONFIG!$J$62,0,0,COUNTA(CONFIG!$J$62:$J$140),1)
Name ListaTipo: OFFSET(CONFIG!$L$62,0,0,COUNTA(CONFIG!$L$62:$L$140),1)
Name ListaStatiAtt: OFFSET(CONFIG!$N$62,0,0,COUNTA(CONFIG!$N$62:$N$140),1)
Name BudgetVoli: CONFIG!$B$36
Name BudgetAlloggio: CONFIG!$B$37
Name BudgetTrasporti: CONFIG!$B$38
Name BudgetIngressi: CONFIG!$B$39
Name BudgetCibo: CONFIG!$B$40
Name BudgetPersonali: CONFIG!$B$41
Name BudgetSouvenir: CONFIG!$B$42
Name BudgetAssicurazione: CONFIG!$B$43
Name BudgetESIM: CONFIG!$B$44
Name BudgetBagagli: CONFIG!$B$45
Name BudgetExtra: CONFIG!$B$46
Name Spese_Categoria: SPESE!$C$5:$C$124
Name Spese_ImportoTot: SPESE!$G$5:$G$124
Name Spese_PagatoDa: SPESE!$H$5:$H$124
Name Spese_P1: SPESE!$I$5:$I$124
Name Spese_P2: SPESE!$J$5:$J$124
Name Spese_P3: SPESE!$K$5:$K$124
Name Spese_QuotaPax: SPESE!$M$5:$M$124
Name Pren_Stato: PRENOTAZIONI!$N$5:$N$54
Name Pren_Voce: PRENOTAZIONI!$A$5:$A$54
Name Att_Giorno: 'ATTIVITÀ'!$A$5:$A$300
Name Att_Stato: 'ATTIVITÀ'!$I$5:$I$300
Name Att_Attivita: 'ATTIVITÀ'!$D$5:$D$300

Sheet DASHBOARD
A1: Giappone 2026 — Companion
A2: Dashboard dinamica: si aggiorna da sola da CONFIG, SPESE, PRENOTAZIONI.
A10: Giorni alla partenza | E10: Budget gruppo € | I10: Speso gruppo € | M10: Residuo €
A11: =IF(TODAY()<DataPartenza,DataPartenza-TODAY(),IF(TODAY()<=DataRitorno,"in viaggio","concluso")) | E11: =Budget_Target_Pax*N_Persone | I11: =SUM(Spese_ImportoTot) | M11: =Budget_Target_Pax*N_Persone-SUM(Spese_ImportoTot)
A12: ="Prenotazioni: " & (COUNTIF(Pren_Stato,"Pagato")+COUNTIF(Pren_Stato,"Prenotato")) & "/" & COUNTA(Pren_Voce) & " · Attività: " & COUNTIF(Att_Stato,"Fatto") & "/" & COUNTA(Att_Attivita) & " completate · Utilizzo budget: " & TEXT(SUM(Spese_ImportoTot)/(Budget_Target_Pax*N_Persone),"0%")
A14: PROSSIME SCADENZE | H14: SALDO PER PERSONA
A15: Data | B15: Cosa | E15: Giorni | F15: Stato | H15: Persona | I15: Anticipato | J15: Quota | K15: Saldo | L15: Stato | M15: Nota
A16: =IF(SCADENZE!A5="","",SCADENZE!A5) | B16: =IF(SCADENZE!B5="","",SCADENZE!B5) | E16: =IF(SCADENZE!E5="","",SCADENZE!E5) | F16: =IF(SCADENZE!F5="","",SCADENZE!F5) | H16: =SALDI!A5 | I16: =SALDI!B5 | J16: =SALDI!C5 | K16: =SALDI!D5 | L16: =SALDI!E5 | M16: =IF(SALDI!B5=0,"—","compila 'Pagato da' in SPESE")
A17: =IF(SCADENZE!A6="","",SCADENZE!A6) | B17: =IF(SCADENZE!B6="","",SCADENZE!B6) | E17: =IF(SCADENZE!E6="","",SCADENZE!E6) | F17: =IF(SCADENZE!F6="","",SCADENZE!F6) | H17: =SALDI!A6 | I17: =SALDI!B6 | J17: =SALDI!C6 | K17: =SALDI!D6 | L17: =SALDI!E6 | M17: =IF(SALDI!B6=0,"—","compila 'Pagato da' in SPESE")
A18: =IF(SCADENZE!A7="","",SCADENZE!A7) | B18: =IF(SCADENZE!B7="","",SCADENZE!B7) | E18: =IF(SCADENZE!E7="","",SCADENZE!E7) | F18: =IF(SCADENZE!F7="","",SCADENZE!F7) | H18: =SALDI!A7 | I18: =SALDI!B7 | J18: =SALDI!C7 | K18: =SALDI!D7 | L18: =SALDI!E7 | M18: =IF(SALDI!B7=0,"—","compila 'Pagato da' in SPESE")
A19: =IF(SCADENZE!A8="","",SCADENZE!A8) | B19: =IF(SCADENZE!B8="","",SCADENZE!B8) | E19: =IF(SCADENZE!E8="","",SCADENZE!E8) | F19: =IF(SCADENZE!F8="","",SCADENZE!F8)
A20: =IF(SCADENZE!A9="","",SCADENZE!A9) | B20: =IF(SCADENZE!B9="","",SCADENZE!B9) | E20: =IF(SCADENZE!E9="","",SCADENZE!E9) | F20: =IF(SCADENZE!F9="","",SCADENZE!F9)
A21: =IF(SCADENZE!A10="","",SCADENZE!A10) | B21: =IF(SCADENZE!B10="","",SCADENZE!B10) | E21: =IF(SCADENZE!E10="","",SCADENZE!E10) | F21: =IF(SCADENZE!F10="","",SCADENZE!F10)
A22: =IF(SCADENZE!A11="","",SCADENZE!A11) | B22: =IF(SCADENZE!B11="","",SCADENZE!B11) | E22: =IF(SCADENZE!E11="","",SCADENZE!E11) | F22: =IF(SCADENZE!F11="","",SCADENZE!F11)
A23: =IF(SCADENZE!A12="","",SCADENZE!A12) | B23: =IF(SCADENZE!B12="","",SCADENZE!B12) | E23: =IF(SCADENZE!E12="","",SCADENZE!E12) | F23: =IF(SCADENZE!F12="","",SCADENZE!F12)
A25: GRAFICI
I45: Legenda stati • Da fare / Da pianificare → giallo • Prenotato → azzurro • Pagato / Fatto → verde • Annullato / Scaduta → rosso • Opzionale → grigio

Sheet ITINERARIO
A1: ITINERARIO — Giappone 2026
A2: 15 giorni · 23 ott – 7 nov 2026 · Roma → KIX → Izumisano → Osaka → Hiroshima → Nara → Kyoto → Tokyo. Budget per persona.
A4: Giorno | B4: Data | C4: Giorno sett. | D4: Base/Città | E4: Titolo | F4: Difficoltà | G4: Cibo € | H4: Trasporti € | I4: Ingressi € | J4: Totale € | K4: Attività principali | L4: Fatte | M4: Note / Piano B
A5: 1 | B5: 46318 | C5: =CHOOSE(WEEKDAY(B5,2),"Lun","Mar","Mer","Gio","Ven","Sab","Dom") | D5: Roma → KIX | E5: Partenza & Arrivo KIX (Izumisano) | F5: 1 | G5: 15 | H5: 10 | I5: 0 | J5: =SUM(G5:I5) | K5: Volo MU788 (FCO→PVG) + FM3051 (PVG→KIX) · arrivo 21:00 · Nankai → Izumisano · KURA Hotel | L5: =IF(COUNTIF(Att_Giorno,A5)=0,"—",COUNTIFS(Att_Giorno,A5,Att_Stato,"Fatto")&"/"&COUNTIF(Att_Giorno,A5)) | M5: Volo notturno, scalo Shanghai 2h45 · pasto speciale Rebecca
A6: 2 | B6: 46320 | C6: =CHOOSE(WEEKDAY(B6,2),"Lun","Mar","Mer","Gio","Ven","Sab","Dom") | D6: Osaka | E6: Trasferimento a Osaka · Shinsaibashi & Dotonbori | F6: 2 | G6: 25 | H6: 14 | I6: 0 | J6: =SUM(G6:I6) | K6: Nankai Izumisano→Namba · Shinsaibashi shopping · Tempio Hozen-ji · Dotonbori illuminato | L6: =IF(COUNTIF(Att_Giorno,A6)=0,"—",COUNTIFS(Att_Giorno,A6,Att_Stato,"Fatto")&"/"&COUNTIF(Att_Giorno,A6)) | M6: Piano B pioggia: Namba Walk coperto
A7: 3 | B7: 46321 | C7: =CHOOSE(WEEKDAY(B7,2),"Lun","Mar","Mer","Gio","Ven","Sab","Dom") | D7: Osaka | E7: Osaka: Cultura & Quartieri | F7: 3 | G7: 30 | H7: 8 | I7: 8 | J7: =SUM(G7:I7) | K7: Castello di Osaka · Shitenno-ji · Shinsekai · Tsutenkaku (opz.) · Nipponbashi Den Den Town ⭐Lorenzo | L7: =IF(COUNTIF(Att_Giorno,A7)=0,"—",COUNTIFS(Att_Giorno,A7,Att_Stato,"Fatto")&"/"&COUNTIF(Att_Giorno,A7)) | M7: Umeda rimosso: giornata tranquilla in zona Minami
A8: 4 | B8: 46322 | C8: =CHOOSE(WEEKDAY(B8,2),"Lun","Mar","Mer","Gio","Ven","Sab","Dom") | D8: Osaka | E8: Universal Studios Japan | F8: 4 | G8: 25 | H8: 5 | I8: 88 | J8: =SUM(G8:I8) | K8: USJ: Super Nintendo World · Harry Potter · Minion/Jurassic · voucher pasto incluso | L8: =IF(COUNTIF(Att_Giorno,A8)=0,"—",COUNTIFS(Att_Giorno,A8,Att_Stato,"Fatto")&"/"&COUNTIF(Att_Giorno,A8)) | M8: Biglietto 88 €/pax (05/09) · portare QR · Rebecca porta cibo da casa
A9: 5 | B9: 46323 | C9: =CHOOSE(WEEKDAY(B9,2),"Lun","Mar","Mer","Gio","Ven","Sab","Dom") | D9: Hiroshima + Miyajima | E9: Hiroshima + Miyajima | F9: 4 | G9: 25 | H9: 0 | I9: 5 | J9: =SUM(G9:I9) | K9: Attivazione JR Pass · Shinkansen Sakura → Hiroshima · traghetto Miyajima · Itsukushima · Museo della Pace | L9: =IF(COUNTIF(Att_Giorno,A9)=0,"—",COUNTIFS(Att_Giorno,A9,Att_Stato,"Fatto")&"/"&COUNTIF(Att_Giorno,A9)) | M9: Sveglia 05:15 · attivare JR Kansai-Hiroshima (28/09!) · maree Miyajima
A10: 6 | B10: 46324 | C10: =CHOOSE(WEEKDAY(B10,2),"Lun","Mar","Mer","Gio","Ven","Sab","Dom") | D10: Nara → Kyoto | E10: Nara + Arrivo Kyoto | F10: 3 | G10: 30 | H10: 7 | I10: 10 | J10: =SUM(G10:I10) | K10: Check-out Osaka · Takkyubin valigie → Tokyo · Kintetsu Nara · Todaiji · Fushimi Inari sera | L10: =IF(COUNTIF(Att_Giorno,A10)=0,"—",COUNTIFS(Att_Giorno,A10,Att_Stato,"Fatto")&"/"&COUNTIF(Att_Giorno,A10)) | M10: Bagagli spediti (consegna 1 nov) · solo bagaglio a mano
A11: 7 | B11: 46325 | C11: =CHOOSE(WEEKDAY(B11,2),"Lun","Mar","Mer","Gio","Ven","Sab","Dom") | D11: Kyoto | E11: Kyoto: Higashiyama & Gion | F11: 4 | G11: 30 | H11: 8 | I11: 6 | J11: =SUM(G11:I11) | K11: Sannenzaka/Ninenzaka · Kodai-ji · Yasaka · Gion · Kiyomizu-dera al tramonto ~17:15 | L11: =IF(COUNTIF(Att_Giorno,A11)=0,"—",COUNTIFS(Att_Giorno,A11,Att_Stato,"Fatto")&"/"&COUNTIF(Att_Giorno,A11)) | M11: Ultimo ingresso Kiyomizu ~17:30
A12: 8 | B12: 46326 | C12: =CHOOSE(WEEKDAY(B12,2),"Lun","Mar","Mer","Gio","Ven","Sab","Dom") | D12: Kyoto | E12: Kyoto: Templi del Nord + Uzumasa + Halloween | F12: 3 | G12: 30 | H12: 8 | I12: 20 | J12: =SUM(G12:I12) | K12: Kinkaku-ji · Ryoan-ji · Uzumasa Kyoto Village (EVA, ultimo ingresso 17:15) · Halloween a Gion | L12: =IF(COUNTIF(Att_Giorno,A12)=0,"—",COUNTIFS(Att_Giorno,A12,Att_Stato,"Fatto")&"/"&COUNTIF(Att_Giorno,A12)) | M12: Uzumasa ¥2.800 · alternativa EN Tea Ceremony
A13: 9 | B13: 46327 | C13: =CHOOSE(WEEKDAY(B13,2),"Lun","Mar","Mer","Gio","Ven","Sab","Dom") | D13: Kyoto → Tokyo | E13: Kyoto→Tokyo via Shinkansen | F13: 2 | G13: 25 | H13: 86 | I13: 13 | J13: =SUM(G13:I13) | K13: Shinkansen Hikari (¥13.650) · arrivo Tokyo · Skytree al tramonto · Solamachi | L13: =IF(COUNTIF(Att_Giorno,A13)=0,"—",COUNTIFS(Att_Giorno,A13,Att_Stato,"Fatto")&"/"&COUNTIF(Att_Giorno,A13)) | M13: Prenotare posto riservato dal 1 ott (SmartEX)
A14: 10 | B14: 46328 | C14: =CHOOSE(WEEKDAY(B14,2),"Lun","Mar","Mer","Gio","Ven","Sab","Dom") | D14: Tokyo | E14: Tokyo: Asakusa → Akihabara | F14: 4 | G14: 30 | H14: 10 | I14: 0 | J14: =SUM(G14:I14) | K14: Senso-ji mattina · Nakamise · Akihabara pieno (arcade, Super Potato, Mandarake) · Ameyoko | L14: =IF(COUNTIF(Att_Giorno,A14)=0,"—",COUNTIFS(Att_Giorno,A14,Att_Stato,"Fatto")&"/"&COUNTIF(Att_Giorno,A14)) | M14: Giorni coperti: pioggia ok
A15: 11 | B15: 46329 | C15: =CHOOSE(WEEKDAY(B15,2),"Lun","Mar","Mer","Gio","Ven","Sab","Dom") | D15: Tokyo | E15: Sanrio Puroland + Ikebukuro | F15: 3 | G15: 35 | H15: 12 | I15: 25 | J15: =SUM(G15:I15) | K15: Sanrio Puroland (Day Passport, indoor) · Sunshine City / Pokémon Center MEGA · Animate Ikebukuro | L15: =IF(COUNTIF(Att_Giorno,A15)=0,"—",COUNTIFS(Att_Giorno,A15,Att_Stato,"Fatto")&"/"&COUNTIF(Att_Giorno,A15)) | M15: Sanrio ✅ 09/09 (~19,97 €) · 3 nov = Bunka no Hi
A16: 12 | B16: 46330 | C16: =CHOOSE(WEEKDAY(B16,2),"Lun","Mar","Mer","Gio","Ven","Sab","Dom") | D16: Tokyo | E16: Tokyo: Meiji → Nakano → Shinjuku → Shibuya | F16: 3 | G16: 35 | H16: 10 | I16: 18 | J16: =SUM(G16:I16) | K16: Meiji · Harajuku · Nakano Broadway ⭐Lorenzo · Shinjuku · Shibuya Crossing · Shibuya Sky (opz.) | L16: =IF(COUNTIF(Att_Giorno,A16)=0,"—",COUNTIFS(Att_Giorno,A16,Att_Stato,"Fatto")&"/"&COUNTIF(Att_Giorno,A16)) | M16: Shibuya Sky ¥3.400 tramonto · prenotare 21/10
... A19: 15 | B19: 46333 | C19: =CHOOSE(WEEKDAY(B19,2),"Lun","Mar","Mer","Gio","Ven","Sab","Dom") | D19: Roma | E19: Rientro | F19: 1 | G19: 15 | H19: 15 | I19: 0 | J19: =SUM(G19:I19) | K19: Giorno di recupero a casa — nessuna attivita' pianificata | L19: =IF(COUNTIF(Att_Giorno,A19)=0,"—",COUNTIFS(Att_Giorno,A19,Att_Stato,"Fatto")&"/"&COUNTIF(Att_Giorno,A19)) | M19: Arrivo FCO la sera del 6/11
A20: TOT | D20: Totale / persona | G20: =SUM(G5:G19) | H20: =SUM(H5:H19) | I20: =SUM(I5:I19) | J20: =SUM(J5:J19)

Sheet ATTIVITÀ
A1: ATTIVITÀ — Tracker attività e luoghi
A2: Una riga per attività/luogo. Aggiorna 'Stato' dal menu a tendina: le attività completate aumentano la barra in DASHBOARD.
A4: Giorno | B4: Data | C4: Città | D4: Attività / Luogo | E4: Tipo | F4: Voto | G4: Costo ¥ | H4: Costo € | I4: Stato | J4: Prenotazione | K4: Note / Rebecca
A5: 1 | B5: 46319 | C5: Izumisano (KIX) | D5: Nankai Airport Express KIX→Izumisano | E5: Trasporto | F5: 3 | G5: 520 | H5: =IF(OR(G5="",G5=0),"",G5/Tasso_JPY_EUR) | I5: Da fare | K5: ~10 min
A6: 1 | B6: 46319 | C6: Izumisano (KIX) | D6: Check-in KURA Hotel Izumisano | E6: Alloggio | F6: 4 | H6: =IF(OR(G6="",G6=0),"",G6/Tasso_JPY_EUR) | I6: Da fare | J6: Booking.com | K6: Self check-in · kitchenette
A7: 2 | B7: 46320 | C7: Osaka | D7: Nankai Main Line Izumisano→Namba | E7: Trasporto | F7: 3 | G7: 610 | H7: =IF(OR(G7="",G7=0),"",G7/Tasso_JPY_EUR) | I7: Da fare | K7: ~34 min
A8: 2 | B8: 46320 | C8: Osaka | D8: Shinsaibashi-suji (shopping) | E8: Shopping | F8: 4 | H8: =IF(OR(G8="",G8=0),"",G8/Tasso_JPY_EUR) | I8: Da fare | K8: Negozi ~10:30–20:30
A9: 2 | B9: 46320 | C9: Osaka | D9: Tempio Hozen-ji | E9: Tempio | F9: 4 | H9: =IF(OR(G9="",G9=0),"",G9/Tasso_JPY_EUR) | I9: Da fare | K9: A 2 min da Dotonbori
A10: 2 | B10: 46320 | C10: Osaka | D10: Dotonbori (sera, illuminato) | E10: Quartiere | F10: 5 | H10: =IF(OR(G10="",G10=0),"",G10/Tasso_JPY_EUR) | I10: Da fare | K10: Insegne al neon · street food
A11: 3 | B11: 46321 | C11: Osaka | D11: Castello di Osaka + giardini | E11: Castello | F11: 4 | G11: 600 | H11: =IF(OR(G11="",G11=0),"",G11/Tasso_JPY_EUR) | I11: Da fare | J11: in loco | K11: Apertura 9:00
A12: 3 | B12: 46321 | C12: Osaka | D12: Tempio Shitenno-ji | E12: Tempio | F12: 4 | G12: 500 | H12: =IF(OR(G12="",G12=0),"",G12/Tasso_JPY_EUR) | I12: Da fare | J12: in loco | K12: 9:00–16:30
A13: 3 | B13: 46321 | C13: Osaka | D13: Shinsekai | E13: Quartiere | F13: 4 | H13: =IF(OR(G13="",G13=0),"",G13/Tasso_JPY_EUR) | I13: Da fare | K13: Atmosfera retrò · kushikatsu
A14: 3 | B14: 46321 | C14: Osaka | D14: Torre Tsutenkaku | E14: Attività | F14: 2 | G14: 900 | H14: =IF(OR(G14="",G14=0),"",G14/Tasso_JPY_EUR) | I14: Opzionale | J14: in loco
A15: 3 | B15: 46321 | C15: Osaka | D15: Nipponbashi Den Den Town ⭐Lorenzo | E15: Shopping | F15: 4 | H15: =IF(OR(G15="",G15=0),"",G15/Tasso_JPY_EUR) | I15: Da fare | K15: Osaka's Akihabara · ~2h45
A16: 4 | B16: 46322 | C16: Osaka | D16: USJ — Super Nintendo World | E16: Attività | F16: 4 | H16: =IF(OR(G16="",G16=0),"",G16/Tasso_JPY_EUR) | I16: Da fare | J16: Klook | K16: Orario assegnato · incluso nel biglietto
A17: 4 | B17: 46322 | C17: Osaka | D17: USJ — Harry Potter | E17: Attività | F17: 4 | H17: =IF(OR(G17="",G17=0),"",G17/Tasso_JPY_EUR) | I17: Da fare | J17: Klook | K17: Hogwarts Castle
A18: 4 | B18: 46322 | C18: Osaka | D18: USJ — Minion Park / Jurassic | E18: Attività | F18: 3 | H18: =IF(OR(G18="",G18=0),"",G18/Tasso_JPY_EUR) | I18: Da fare | J18: Klook | K18: Voucher pasto incluso
A19: 5 | B19: 46323 | C19: Hiroshima / Miyajima | D19: Attivazione JR Kansai-Hiroshima Pass | E19: Trasporto | F19: 5 | G19: 17000 | H19: =IF(OR(G19="",G19=0),"",G19/Tasso_JPY_EUR) | I19: Da fare | J19: JR-WEST ONLINE | K19: Ritiro/attivazione 28 ott
A20: 5 | B20: 46323 | C20: Hiroshima / Miyajima | D20: Shinkansen Shin-Osaka→Hiroshima | E20: Trasporto | F20: 3 | H20: =IF(OR(G20="",G20=0),"",G20/Tasso_JPY_EUR) | I20: Da fare | K20: Incluso nel pass · ~1h30
A21: 5 | B21: 46323 | C21: Hiroshima / Miyajima | D21: Traghetto JR → Miyajima | E21: Trasporto | F21: 4 | H21: =IF(OR(G21="",G21=0),"",G21/Tasso_JPY_EUR) | I21: Da fare | K21: Incluso nel pass · tassa 100 ¥
A22: 5 | B22: 46323 | C22: Hiroshima / Miyajima | D22: Itsukushima Shrine (torii) | E22: Tempio | F22: 5 | G22: 300 | H22: =IF(OR(G22="",G22=0),"",G22/Tasso_JPY_EUR) | I22: Da fare | J22: in loco | K22: Verificare orari maree
A23: 5 | B23: 46323 | C23: Hiroshima / Miyajima | D23: Tempio Daisho-in | E23: Tempio | F23: 3 | H23: =IF(OR(G23="",G23=0),"",G23/Tasso_JPY_EUR) | I23: Da fare | K23: 8:00–17:00
A24: 5 | B24: 46323 | C24: Hiroshima / Miyajima | D24: Museo della Pace Hiroshima | E24: Museo | F24: 4 | G24: 200 | H24: =IF(OR(G24="",G24=0),"",G24/Tasso_JPY_EUR) | I24: Da fare | J24: Klook/Asoview | K24: Slot 30' · ~2h
A25: 5 | B25: 46323 | C25: Hiroshima / Miyajima | D25: Genbaku Dome / Peace Park | E25: Monumento | F25: 5 | H25: =IF(OR(G25="",G25=0),"",G25/Tasso_JPY_EUR) | I25: Da fare | K25: UNESCO · gratuito
A26: 5 | B26: 46323 | C26: Hiroshima / Miyajima | D26: Hondori street | E26: Shopping | F26: 3 | H26: =IF(OR(G26="",G26=0),"",G26/Tasso_JPY_EUR) | I26: Opzionale | K26: Momiji manju · uscire 17:30
A27: 6 | B27: 46324 | C27: Nara / Kyoto | D27: Takkyubin valigie Osaka→Tokyo | E27: Logistica | F27: 4 | G27: 9480 | H27: =IF(OR(G27="",G27=0),"",G27/Tasso_JPY_EUR) | I27: Da fare | J27: Yamato | K27: 3 valigie · consegna 1 nov
A28: 6 | B28: 46324 | C28: Nara / Kyoto | D28: Kintetsu Namba→Nara | E28: Trasporto | F28: 3 | G28: 570 | H28: =IF(OR(G28="",G28=0),"",G28/Tasso_JPY_EUR) | I28: Da fare | K28: Non-JR · ~40 min
A29: 6 | B29: 46324 | C29: Nara / Kyoto | D29: Parco di Nara (cervi) | E29: Natura | F29: 4 | H29: =IF(OR(G29="",G29=0),"",G29/Tasso_JPY_EUR) | I29: Da fare | K29: Shika senbei 150 ¥
A30: 6 | B30: 46324 | C30: Nara / Kyoto | D30: Tempio Todaiji (Gran Buddha) | E30: Tempio | F30: 5 | G30: 800 | H30: =IF(OR(G30="",G30=0),"",G30/Tasso_JPY_EUR) | I30: Da fare | J30: in loco | K30: Daibutsu 15 m
A31: 6 | B31: 46324 | C31: Nara / Kyoto | D31: Santuario Kasuga Taisha | E31: Tempio | F31: 3 | H31: =IF(OR(G31="",G31=0),"",G31/Tasso_JPY_EUR) | I31: Da fare | K31: 3.000 lanterne
A32: 6 | B32: 46324 | C32: Nara / Kyoto | D32: Fushimi Inari (sera) | E32: Tempio | F32: 3 | H32: =IF(OR(G32="",G32=0),"",G32/Tasso_JPY_EUR) | I32: Da fare | K32: 24h · JR 5 min dal pass
A33: 7 | B33: 46325 | C33: Kyoto | D33: Sannenzaka & Ninenzaka | E33: Quartiere | F33: 4 | H33: =IF(OR(G33="",G33=0),"",G33/Tasso_JPY_EUR) | I33: Da fare | K33: Viuzze acciottolate
A34: 7 | B34: 46325 | C34: Kyoto | D34: Tempio Kodai-ji | E34: Tempio | F34: 3 | G34: 600 | H34: =IF(OR(G34="",G34=0),"",G34/Tasso_JPY_EUR) | I34: Da fare | J34: in loco | K34: 9:00–17:00
A35: 7 | B35: 46325 | C35: Kyoto | D35: Nishiki Market | E35: Mercato | F35: 4 | H35: =IF(OR(G35="",G35=0),"",G35/Tasso_JPY_EUR) | I35: Da fare | K35: Attenzione: alcuni negozi chiusi il mercoledì
A36: 7 | B36: 46325 | C36: Kyoto | D36: Santuario Yasaka | E36: Tempio | F36: 4 | H36: =IF(OR(G36="",G36=0),"",G36/Tasso_JPY_EUR) | I36: Da fare | K36: 24h · gratuito
A37: 7 | B37: 46325 | C37: Kyoto | D37: Quartiere Gion | E37: Quartiere | F37: 2 | H37: =IF(OR(G37="",G37=0),"",G37/Tasso_JPY_EUR) | I37: Da fare | K37: Vietato vicoli privati (multa)
A38: 7 | B38: 46325 | C38: Kyoto | D38: Kiyomizu-dera al tramonto | E38: Tempio | F38: 5 | G38: 500 | H38: =IF(OR(G38="",G38=0),"",G38/Tasso_JPY_EUR) | I38: Da fare | J38: in loco | K38: Ultimo ingresso ~17:30
A39: 8 | B39: 46326 | C39: Kyoto | D39: Kinkaku-ji (Padiglione d'Oro) | E39: Tempio | F39: 3 | G39: 500 | H39: =IF(OR(G39="",G39=0),"",G39/Tasso_JPY_EUR) | I39: Da fare | J39: in loco | K39: 9:00–17:00
A40: 8 | B40: 46326 | C40: Kyoto | D40: Ryoan-ji | E40: Tempio | F40: 2 | G40: 600 | H40: =IF(OR(G40="",G40=0),"",G40/Tasso_JPY_EUR) | I40: Opzionale | J40: in loco | K40: Giardino zen di rocce
A41: 8 | B41: 46326 | C41: Kyoto | D41: Uzumasa Kyoto Village + EVA | E41: Attività | F41: 3 | G41: 2800 | H41: =IF(OR(G41="",G41=0),"",G41/Tasso_JPY_EUR) | I41: Da fare | J41: ticket.eigamura.com | K41: EVA ultimo ingresso 17:15
...

Sheet PRENOTAZIONI
A1: PRENOTAZIONI — Tracker prenotazioni & scadenze
A2: Tutto cio' che va prenotato/acquistato. I giorni rimanenti si aggiornano da soli (TODAY).
A4: Voce | B4: Categoria | C4: Data/Giorno | D4: Finestra apertura | E4: Scadenza | F4: Giorni | G4: Canale | H4: Importo | I4: Valuta | J4: Tipo | K4: Importo unit. € | L4: Importo tot. € | M4: Importo/pax € | N4: Stato | O4: Codice conferma | P4: Priorità | Q4: Note
A5: Voli A/R China Eastern (open-jaw) | B5: Voli | C5: 23 ott / 6 nov | D5: — | F5: =IF(E5="","",E5-TODAY()) | G5: China Eastern | H5: 1096.33 | I5: EUR | J5: A testa | K5: =IF(H5="","",IF(UPPER(I5)="JPY",H5/Tasso_JPY_EUR,H5)) | L5: =IF(H5="","",K5*IF(LEFT(UPPER(J5),1)="A",N_Persone,1)) | M5: =IF(H5="","",IF(LEFT(UPPER(J5),1)="A",K5,K5/N_Persone)) | N5: Pagato | P5: Alta | Q5: FCO→KIX + HND→FCO · tot 3.289 € · ordine 09/08/26
A6: Alloggio KURA Hotel Izumisano | B6: Alloggio | C6: 24–25 ott | D6: — | F6: =IF(E6="","",E6-TODAY()) | G6: Booking.com | H6: 26.67 | I6: EUR | J6: A testa | K6: =IF(H6="","",IF(UPPER(I6)="JPY",H6/Tasso_JPY_EUR,H6)) | L6: =IF(H6="","",K6*IF(LEFT(UPPER(J6),1)="A",N_Persone,1)) | M6: =IF(H6="","",IF(LEFT(UPPER(J6),1)="A",K6,K6/N_Persone)) | N6: Pagato | P6: Alta | Q6: Self check-in · kitchenette
A7: Alloggio Hanazonocho Apartment 103 (Osaka) | B7: Alloggio | C7: 25–29 ott | D7: — | F7: =IF(E7="","",E7-TODAY()) | G7: Booking.com / Airbnb | H7: 74.33 | I7: EUR | J7: A testa | K7: =IF(H7="","",IF(UPPER(I7)="JPY",H7/Tasso_JPY_EUR,H7)) | L7: =IF(H7="","",K7*IF(LEFT(UPPER(J7),1)="A",N_Persone,1)) | M7: =IF(H7="","",IF(LEFT(UPPER(J7),1)="A",K7,K7/N_Persone)) | N7: Pagato | P7: Alta | Q7: Angolo cottura · metro 1 min
A8: Alloggio Miro Kyoto Nijo Hotel | B8: Alloggio | C8: 29 ott–1 nov | D8: — | F8: =IF(E8="","",E8-TODAY()) | G8: Booking.com | H8: 85.72 | I8: EUR | J8: A testa | K8: =IF(H8="","",IF(UPPER(I8)="JPY",H8/Tasso_JPY_EUR,H8)) | L8: =IF(H8="","",K8*IF(LEFT(UPPER(J8),1)="A",N_Persone,1)) | M8: =IF(H8="","",IF(LEFT(UPPER(J8),1)="A",K8,K8/N_Persone)) | N8: Pagato | P8: Alta | Q8: Cucina attrezzata · tel +81-50-5444-6620
A9: Alloggio Taito City Guesthouse (Tokyo) | B9: Alloggio | C9: 1–6 nov | D9: — | F9: =IF(E9="","",E9-TODAY()) | G9: Booking.com | H9: 173.17 | I9: EUR | J9: A testa | K9: =IF(H9="","",IF(UPPER(I9)="JPY",H9/Tasso_JPY_EUR,H9)) | L9: =IF(H9="","",K9*IF(LEFT(UPPER(J9),1)="A",N_Persone,1)) | M9: =IF(H9="","",IF(LEFT(UPPER(J9),1)="A",K9,K9/N_Persone)) | N9: Pagato | P9: Alta | Q9: Cucina condivisa 1° piano · confermare ricezione bagagli
A10: Universal Studios Japan (1-day + SNW + voucher) | B10: Ingressi/Attività | C10: 27 ott | D10: — | F10: =IF(E10="","",E10-TODAY()) | G10: Klook / ufficiale | H10: 88.25 | I10: EUR | J10: A testa | K10: =IF(H10="","",IF(UPPER(I10)="JPY",H10/Tasso_JPY_EUR,H10)) | L10: =IF(H10="","",K10*IF(LEFT(UPPER(J10),1)="A",N_Persone,1)) | M10: =IF(H10="","",IF(LEFT(UPPER(J10),1)="A",K10,K10/N_Persone)) | N10: Prenotato | P10: Alta | Q10: Acquistato 05/09 · portare QR · Express Pass non incluso
A11: Sanrio Puroland (Day Passport + riserva) | B11: Ingressi/Attività | C11: 3 nov | D11: — | F11: =IF(E11="","",E11-TODAY()) | G11: e-Passport / Klook | H11: 19.97 | I11: EUR | J11: A testa | K11: =IF(H11="","",IF(UPPER(I11)="JPY",H11/Tasso_JPY_EUR,H11)) | L11: =IF(H11="","",K11*IF(LEFT(UPPER(J11),1)="A",N_Persone,1)) | M11: =IF(H11="","",IF(LEFT(UPPER(J11),1)="A",K11,K11/N_Persone)) | N11: Prenotato | P11: Alta | Q11: Prenotato 09/09 · annotare n. conferma/orario · chiuso 4-5 nov
A12: Assicurazione sanitaria | B12: Assicurazione | C12: — | D12: — | F12: =IF(E12="","",E12-TODAY()) | G12: Heymondo (da confermare) | H12: 53.43 | I12: EUR | J12: A testa | K12: =IF(H12="","",IF(UPPER(I12)="JPY",H12/Tasso_JPY_EUR,H12)) | L12: =IF(H12="","",K12*IF(LEFT(UPPER(J12),1)="A",N_Persone,1)) | M12: =IF(H12="","",IF(LEFT(UPPER(J12),1)="A",K12,K12/N_Persone)) | N12: Prenotato | P12: Alta | Q12: Annotare provider + n. polizza · copertura allergie Rebecca da verificare
A13: JR Kansai-Hiroshima Area Pass (5gg) | B13: Trasporti | C13: attivo 28 ott | D13: 28 set 10:00 JST | E13: 46293 | F13: =IF(E13="","",E13-TODAY()) | G13: JR-WEST ONLINE | H13: 17000 | I13: JPY | J13: A testa | K13: =IF(H13="","",IF(UPPER(I13)="JPY",H13/Tasso_JPY_EUR,H13)) | L13: =IF(H13="","",K13*IF(LEFT(UPPER(J13),1)="A",N_Persone,1)) | M13: =IF(H13="","",IF(LEFT(UPPER(J13),1)="A",K13,K13/N_Persone)) | N13: Da fare | P13: Alta | Q13: Acquistare su JR-WEST ONLINE per prenotare i posti online · ritiro/attivazione 28 ott
A14: Posti riservati Shin-Osaka→Hiroshima | B14: Trasporti | C14: 28 ott | D14: 28 set 10:00 JST | E14: 46293 | F14: =IF(E14="","",E14-TODAY()) | G14: JR-WEST Online | H14: 0 | I14: JPY | J14: A testa | K14: =IF(H14="","",IF(UPPER(I14)="JPY",H14/Tasso_JPY_EUR,H14)) | L14: =IF(H14="","",K14*IF(LEFT(UPPER(J14),1)="A",N_Persone,1)) | M14: =IF(H14="","",IF(LEFT(UPPER(J14),1)="A",K14,K14/N_Persone)) | N14: Da fare | P14: Alta | Q14: Gratis con il pass · Sakura ~06:45
A15: Posti riservati Hiroshima→Shin-Osaka | B15: Trasporti | C15: 28 ott | D15: 28 set 10:00 JST | E15: 46293 | F15: =IF(E15="","",E15-TODAY()) | G15: JR-WEST Online | H15: 0 | I15: JPY | J15: A testa | K15: =IF(H15="","",IF(UPPER(I15)="JPY",H15/Tasso_JPY_EUR,H15)) | L15: =IF(H15="","",K15*IF(LEFT(UPPER(J15),1)="A",N_Persone,1)) | M15: =IF(H15="","",IF(LEFT(UPPER(J15),1)="A",K15,K15/N_Persone)) | N15: Da fare | P15: Alta | Q15: Gratis con il pass · ritorno ~18:15
A16: Kyoto→Tokyo Shinkansen Hikari (riservato) | B16: Trasporti | C16: 1 nov | D16: 1 ott 10:00 JST | E16: 46296 | F16: =IF(E16="","",E16-TODAY()) | G16: SmartEX | H16: 13650 | I16: JPY | J16: A testa | K16: =IF(H16="","",IF(UPPER(I16)="JPY",H16/Tasso_JPY_EUR,H16)) | L16: =IF(H16="","",K16*IF(LEFT(UPPER(J16),1)="A",N_Persone,1)) | M16: =IF(H16="","",IF(LEFT(UPPER(J16),1)="A",K16,K16/N_Persone)) | N16: Da fare | P16: Alta | Q16: Hayatoku 21 se entro 11 ott · ~2h40
A17: Tokyo Skytree | B17: Ingressi/Attività | C17: 1 nov (dom) | D17: ~2 ott 00:00 JST | E17: 46297 | F17: =IF(E17="","",E17-TODAY()) | G17: sito ufficiale / Klook | H17: 2300 | I17: JPY | J17: A testa | K17: =IF(H17="","",IF(UPPER(I17)="JPY",H17/Tasso_JPY_EUR,H17)) | L17: =IF(H17="","",K17*IF(LEFT(UPPER(J17),1)="A",N_Persone,1)) | M17: =IF(H17="","",IF(LEFT(UPPER(J17),1)="A",K17,K17/N_Persone)) | N17: Da fare | P17: Media | Q17: Weekend ~¥2.600 in loco · salita al tramonto ~16:40
A18: Uzumasa Kyoto Village (Evangelion / EVA) | B18: Ingressi/Attività | C18: 31 ott | D18: vendita anticipata | F18: =IF(E18="","",E18-TODAY()) | G18: ticket.eigamura.com | H18: 2800 | I18: JPY | J18: A testa | K18: =IF(H18="","",IF(UPPER(I18)="JPY",H18/Tasso_JPY_EUR,H18)) | L18: =IF(H18="","",K18*IF(LEFT(UPPER(J18),1)="A",N_Persone,1)) | M18: =IF(H18="","",IF(LEFT(UPPER(J18),1)="A",K18,K18/N_Persone)) | N18: Da fare | P18: Media | Q18: EVA ultimo ingresso 17:15 · entrare entro ~16:00
A19: Shibuya Sky ⭐ Rebecca | B19: Ingressi/Attività | C19: 4 nov | D19: 21 ott 00:00 JST | E19: 46316 | F19: =IF(E19="","",E19-TODAY()) | G19: shibuya-sky.com / Webket | H19: 3400 | I19: JPY | J19: A testa | K19: =IF(H19="","",IF(UPPER(I19)="JPY",H19/Tasso_JPY_EUR,H19)) | L19: =IF(H19="","",K19*IF(LEFT(UPPER(J19),1)="A",N_Persone,1)) | M19: =IF(H19="","",IF(LEFT(UPPER(J19),1)="A",K19,K19/N_Persone)) | N19: Da fare | P19: Alta | Q19: Slot tramonto (dalle 15:00) · prenotare subito all'apertura
A20: Museo della Pace Hiroshima (slot web) | B20: Ingressi/Attività | C20: 28 ott | D20: 90 gg (aperta) | F20: =IF(E20="","",E20-TODAY()) | G20: Klook / Asoview | H20: 200 | I20: JPY | J20: A testa | K20: =IF(H20="","",IF(UPPER(I20)="JPY",H20/Tasso_JPY_EUR,H20)) | L20: =IF(H20="","",K20*IF(LEFT(UPPER(J20),1)="A",N_Persone,1)) | M20: =IF(H20="","",IF(LEFT(UPPER(J20),1)="A",K20,K20/N_Persone)) | N20: Da fare | P20: Media | Q20: Slot 30' · di giorno ok anche in cassa
A21: Tokyo Tower | B21: Ingressi/Attività | C21: 5 nov | D21: nessuna | F21: =IF(E21="","",E21-TODAY()) | G21: cassa / online | H21: 1500 | I21: JPY | J21: A testa | K21: =IF(H21="","",IF(UPPER(I21)="JPY",H21/Tasso_JPY_EUR,H21)) | L21: =IF(H21="","",K21*IF(LEFT(UPPER(J21),1)="A",N_Persone,1)) | M21: =IF(H21="","",IF(LEFT(UPPER(J21),1)="A",K21,K21/N_Persone)) | N21: Da fare | P21: Bassa | Q21: ¥1.500 stesso prezzo
A22: Takkyubin valigie Osaka→Tokyo (3 valigie) | B22: Bagagli | C22: 29 ott (consegna 1 nov) | D22: — | F22: =IF(E22="","",E22-TODAY()) | G22: Yamato Namba Station Center | H22: 9480 | I22: JPY | J22: Totale | K22: =IF(H22="","",IF(UPPER(I22)="JPY",H22/Tasso_JPY_EUR,H22)) | L22: =IF(H22="","",K22*IF(LEFT(UPPER(J22),1)="A",N_Persone,1)) | M22: =IF(H22="","",IF(LEFT(UPPER(J22),1)="A",K22,K22/N_Persone)) | N22: Da fare | P22: Alta | Q22: ¥3.160/valigia · confermare host Tokyo · non spedire valori/documenti
A23: eSIM Giappone | B23: eSIM | C23: pre-partenza | D23: ~2 settimane prima | E23: 46309 | F23: =IF(E23="","",E23-TODAY()) | G23: Klook / Airalo | H23: 20 | I23: EUR | J23: A testa | K23: =IF(H23="","",IF(UPPER(I23)="JPY",H23/Tasso_JPY_EUR,H23)) | L23: =IF(H23="","",K23*IF(LEFT(UPPER(J23),1)="A",N_Persone,1)) | M23: =IF(H23="","",IF(LEFT(UPPER(J23),1)="A",K23,K23/N_Persone)) | N23: Da fare | P23: Alta | Q23: Attivare prima della partenza
A24: Pasto speciale Rebecca (China Eastern) | B24: Extra | C24: 23 ott / 6 nov | D24: pre-partenza | F24: =IF(E24="","",E24-TODAY()) | G24: China Eastern | H24: 0 | I24: EUR | J24: A testa | K24: =IF(H24="","",IF(UPPER(I24)="JPY",H24/Tasso_JPY_EUR,H24)) | L24: =IF(H24="","",K24*IF(LEFT(UPPER(J24),1)="A",N_Persone,1)) | M24: =IF(H24="","",IF(LEFT(UPPER(J24),1)="A",K24,K24/N_Persone)) | N24: Da fare | P24: Alta | Q24: No soia/pesce/crostacei/frutta secca · verificare entrambi i segmenti + scalo PVG
A25: Express Pass USJ (opzionale) | B25: Ingressi/Attività | C25: 27 ott | D25: — | F25: =IF(E25="","",E25-TODAY()) | G25: Klook | H25: 8000 | I25: JPY | J25: A testa | K25: =IF(H25="","",IF(UPPER(I25)="JPY",H25/Tasso_JPY_EUR,H25)) | L25: =IF(H25="","",K25*IF(LEFT(UPPER(J25),1)="A",N_Persone,1)) | M25: =IF(H25="","",IF(LEFT(UPPER(J25),1)="A",K25,K25/N_Persone)) | N25: Opzionale | P25: Bassa | Q25: Solo per saltare code 2h+
A26: EN Tea Ceremony (alternativa a Uzumasa) | B26: Ingressi/Attività | C26: 31 ott | D26: — | F26: =IF(E26="","",E26-TODAY()) | G26: asoview / byFood / KKDay | H26: 2500 | I26: JPY | J26: A testa | K26: =IF(H26="","",IF(UPPER(I26)="JPY",H26/Tasso_JPY_EUR,H26)) | L26: =IF(H26="","",K26*IF(LEFT(UPPER(J26),1)="A",N_Persone,1)) | M26: =IF(H26="","",IF(LEFT(UPPER(J26),1)="A",K26,K26/N_Persone)) | N26: Opzionale | P26: Bassa | Q26: Verificare operativita' (segnalazioni chiusura 2024)
A27: Cena anniversario Davide & Rebecca | B27: Cibo | C27: 5 nov | D27: — | F27: =IF(E27="","",E27-TODAY()) | G27: a cura di Rebecca | H27: 0 | I27: EUR | J27: Totale | K27: =IF(H27="","",IF(UPPER(I27)="JPY",H27/Tasso_JPY_EUR,H27)) | L27: =IF(H27="","",K27*IF(LEFT(UPPER(J27),1)="A",N_Persone,1)) | M27: =IF(H27="","",IF(LEFT(UPPER(J27),1)="A",K27,K27/N_Persone)) | N27: Opzionale | P27: Bassa | Q27: Ristorante Rebecca-safe
A28: Verifica maree Miyajima | B28: Extra | C28: 27 ott | D28: giorno prima | E28: 46322 | F28: =IF(E28="","",E28-TODAY()) | G28: — | H28: 0 | I28: EUR | J28: A testa | K28: =IF(H28="","",IF(UPPER(I28)="JPY",H28/Tasso_JPY_EUR,H28)) | L28: =IF(H28="","",K28*IF(LEFT(UPPER(J28),1)="A",N_Persone,1)) | M28: =IF(H28="","",IF(LEFT(UPPER(J28),1)="A",K28,K28/N_Persone)) | N28: Da fare | P28: Media | Q28: Torii piu' scenico con alta marea · tassa visita 100 ¥
A29: Confermare host Tokyo ricezione bagagli | B29: Extra | C29: entro 29 ott | D29: — | E29: 46324 | F29: =IF(E29="","",E29-TODAY()) | G29: — | H29: 0 | I29: EUR | J29: A testa | K29: =IF(H29="","",IF(UPPER(I29)="JPY",H29/Tasso_JPY_EUR,H29)) | L29: =IF(H29="","",K29*IF(LEFT(UPPER(J29),1)="A",N_Persone,1)) | M29: =IF(H29="","",IF(LEFT(UPPER(J29),1)="A",K29,K29/N_Persone)) | N29: Da fare | P29: Alta | Q29: Private lodging puo' rifiutare la consegna differita
F30: =IF(E30="","",E30-TODAY()) | K30: =IF(H30="","",IF(UPPER(I30)="JPY",H30/Tasso_JPY_EUR,H30)) | L30: =IF(H30="","",K30*IF(LEFT(UPPER(J30),1)="A",N_Persone,1)) | M30: =IF(H30="","",IF(LEFT(UPPER(J30),1)="A",K30,K30/N_Persone))
F31: =IF(E31="","",E31-TODAY()) | K31: =IF(H31="","",IF(UPPER(I31)="JPY",H31/Tasso_JPY_EUR,H31)) | L31: =IF(H31="","",K31*IF(LEFT(UPPER(J31),1)="A",N_Persone,1)) | M31: =IF(H31="","",IF(LEFT(UPPER(J31),1)="A",K31,K31/N_Persone))
F32: =IF(E32="","",E32-TODAY()) | K32: =IF(H32="","",IF(UPPER(I32)="JPY",H32/Tasso_JPY_EUR,H32)) | L32: =IF(H32="","",K32*IF(LEFT(UPPER(J32),1)="A",N_Persone,1)) | M32: =IF(H32="","",IF(LEFT(UPPER(J32),1)="A",K32,K32/N_Persone))
F33: =IF(E33="","",E33-TODAY()) | K33: =IF(H33="","",IF(UPPER(I33)="JPY",H33/Tasso_JPY_EUR,H33)) | L33: =IF(H33="","",K33*IF(LEFT(UPPER(J33),1)="A",N_Persone,1)) | M33: =IF(H33="","",IF(LEFT(UPPER(J33),1)="A",K33,K33/N_Persone))
F34: =IF(E34="","",E34-TODAY()) | K34: =IF(H34="","",IF(UPPER(I34)="JPY",H34/Tasso_JPY_EUR,H34)) | L34: =IF(H34="","",K34*IF(LEFT(UPPER(J34),1)="A",N_Persone,1)) | M34: =IF(H34="","",IF(LEFT(UPPER(J34),1)="A",K34,K34/N_Persone))
F35: =IF(E35="","",E35-TODAY()) | K35: =IF(H35="","",IF(UPPER(I35)="JPY",H35/Tasso_JPY_EUR,H35)) | L35: =IF(H35="","",K35*IF(LEFT(UPPER(J35),1)="A",N_Persone,1)) | M35: =IF(H35="","",IF(LEFT(UPPER(J35),1)="A",K35,K35/N_Persone))
F36: =IF(E36="","",E36-TODAY()) | K36: =IF(H36="","",IF(UPPER(I36)="JPY",H36/Tasso_JPY_EUR,H36)) | L36: =IF(H36="","",K36*IF(LEFT(UPPER(J36),1)="A",N_Persone,1)) | M36: =IF(H36="","",IF(LEFT(UPPER(J36),1)="A",K36,K36/N_Persone))
F37: =IF(E37="","",E37-TODAY()) | K37: =IF(H37="","",IF(UPPER(I37)="JPY",H37/Tasso_JPY_EUR,H37)) | L37: =IF(H37="","",K37*IF(LEFT(UPPER(J37),1)="A",N_Persone,1)) | M37: =IF(H37="","",IF(LEFT(UPPER(J37),1)="A",K37,K37/N_Persone))
F38: =IF(E38="","",E38-TODAY()) | K38: =IF(H38="","",IF(UPPER(I38)="JPY",H38/Tasso_JPY_EUR,H38)) | L38: =IF(H38="","",K38*IF(LEFT(UPPER(J38),1)="A",N_Persone,1)) | M38: =IF(H38="","",IF(LEFT(UPPER(J38),1)="A",K38,K38/N_Persone))
F39: =IF(E39="","",E39-TODAY()) | K39: =IF(H39="","",IF(UPPER(I39)="JPY",H39/Tasso_JPY_EUR,H39)) | L39: =IF(H39="","",K39*IF(LEFT(UPPER(J39),1)="A",N_Persone,1)) | M39: =IF(H39="","",IF(LEFT(UPPER(J39),1)="A",K39,K39/N_Persone))
F40: =IF(E40="","",E40-TODAY()) | K40: =IF(H40="","",IF(UPPER(I40)="JPY",H40/Tasso_JPY_EUR,H40)) | L40: =IF(H40="","",K40*IF(LEFT(UPPER(J40),1)="A",N_Persone,1)) | M40: =IF(H40="","",IF(LEFT(UPPER(J40),1)="A",K40,K40/N_Persone))
F41: =IF(E41="","",E41-TODAY()) | K41: =IF(H41="","",IF(UPPER(I41)="JPY",H41/Tasso_JPY_EUR,H41)) | L41: =IF(H41="","",K41*IF(LEFT(UPPER(J41),1)="A",N_Persone,1)) | M41: =IF(H41="","",IF(LEFT(UPPER(J41),1)="A",K41,K41/N_Persone))
...

Sheet SPESE
A1: SPESE — Registro spese (stile Tricount)
A2: Inserisci l'importo TOTALE, chi ha pagato e spunta con 'X' chi la divide. Importo €, quota/persona e saldi si calcolano da soli.
A4: Data | B4: Giorno | C4: Categoria | D4: Descrizione | E4: Importo | F4: Valuta | G4: Importo € | H4: Pagato da | I4: =CONFIG!$B$15 | J4: =CONFIG!$B$16 | K4: =CONFIG!$B$17 | L4: N° partec. | M4: Quota/persona € | N4: Note
A5: 46243 | B5: =IF(A5="","",IF(A5<DataPartenza,"pre",MAX(1,A5-DataPartenza))) | C5: Voli | D5: Volo A/R China Eastern (open-jaw) | E5: 3288.99 | F5: EUR | G5: =IF(E5="","",IF(UPPER(F5)="JPY",E5/Tasso_JPY_EUR,E5)) | I5: X | J5: X | K5: X | L5: =COUNTIF(I5:K5,"X") | M5: =IF(OR(G5="",L5=0),0,G5/L5) | N5: totale 3 pax · ordine 09/08/26
A6: 46243 | B6: =IF(A6="","",IF(A6<DataPartenza,"pre",MAX(1,A6-DataPartenza))) | C6: Alloggio | D6: KURA Hotel Izumisano (1 notte) | E6: 80.01 | F6: EUR | G6: =IF(E6="","",IF(UPPER(F6)="JPY",E6/Tasso_JPY_EUR,E6)) | I6: X | J6: X | K6: X | L6: =COUNTIF(I6:K6,"X") | M6: =IF(OR(G6="",L6=0),0,G6/L6) | N6: 24–25 ott
A7: 46243 | B7: =IF(A7="","",IF(A7<DataPartenza,"pre",MAX(1,A7-DataPartenza))) | C7: Alloggio | D7: Hanazonocho Apartment 103 (4 notti) | E7: 222.99 | F7: EUR | G7: =IF(E7="","",IF(UPPER(F7)="JPY",E7/Tasso_JPY_EUR,E7)) | I7: X | J7: X | K7: X | L7: =COUNTIF(I7:K7,"X") | M7: =IF(OR(G7="",L7=0),0,G7/L7) | N7: 25–29 ott
A8: 46243 | B8: =IF(A8="","",IF(A8<DataPartenza,"pre",MAX(1,A8-DataPartenza))) | C8: Alloggio | D8: Miro Kyoto Nijo Hotel (3 notti) | E8: 257.16 | F8: EUR | G8: =IF(E8="","",IF(UPPER(F8)="JPY",E8/Tasso_JPY_EUR,E8)) | I8: X | J8: X | K8: X | L8: =COUNTIF(I8:K8,"X") | M8: =IF(OR(G8="",L8=0),0,G8/L8) | N8: 29 ott–1 nov
A9: 46243 | B9: =IF(A9="","",IF(A9<DataPartenza,"pre",MAX(1,A9-DataPartenza))) | C9: Alloggio | D9: Taito City Guesthouse (5 notti) | E9: 519.51 | F9: EUR | G9: =IF(E9="","",IF(UPPER(F9)="JPY",E9/Tasso_JPY_EUR,E9)) | I9: X | J9: X | K9: X | L9: =COUNTIF(I9:K9,"X") | M9: =IF(OR(G9="",L9=0),0,G9/L9) | N9: 1–6 nov
A10: 46270 | B10: =IF(A10="","",IF(A10<DataPartenza,"pre",MAX(1,A10-DataPartenza))) | C10: Ingressi/Attività | D10: USJ 1-day + Super Nintendo World + voucher | E10: 264.75 | F10: EUR | G10: =IF(E10="","",IF(UPPER(F10)="JPY",E10/Tasso_JPY_EUR,E10)) | I10: X | J10: X | K10: X | L10: =COUNTIF(I10:K10,"X") | M10: =IF(OR(G10="",L10=0),0,G10/L10) | N10: 27 ott
A11: 46274 | B11: =IF(A11="","",IF(A11<DataPartenza,"pre",MAX(1,A11-DataPartenza))) | C11: Ingressi/Attività | D11: Sanrio Puroland Day Passport | E11: 59.91 | F11: EUR | G11: =IF(E11="","",IF(UPPER(F11)="JPY",E11/Tasso_JPY_EUR,E11)) | I11: X | J11: X | K11: X | L11: =COUNTIF(I11:K11,"X") | M11: =IF(OR(G11="",L11=0),0,G11/L11) | N11: 3 nov
A12: 46274 | B12: =IF(A12="","",IF(A12<DataPartenza,"pre",MAX(1,A12-DataPartenza))) | C12: Assicurazione | D12: Assicurazione sanitaria | E12: 160.29 | F12: EUR | G12: =IF(E12="","",IF(UPPER(F12)="JPY",E12/Tasso_JPY_EUR,E12)) | I12: X | J12: X | K12: X | L12: =COUNTIF(I12:K12,"X") | M12: =IF(OR(G12="",L12=0),0,G12/L12) | N12: Provider e polizza da annotare
B13: =IF(A13="","",IF(A13<DataPartenza,"pre",MAX(1,A13-DataPartenza))) | G13: =IF(E13="","",IF(UPPER(F13)="JPY",E13/Tasso_JPY_EUR,E13)) | L13: =COUNTIF(I13:K13,"X") | M13: =IF(OR(G13="",L13=0),0,G13/L13)
B14: =IF(A14="","",IF(A14<DataPartenza,"pre",MAX(1,A14-DataPartenza))) | G14: =IF(E14="","",IF(UPPER(F14)="JPY",E14/Tasso_JPY_EUR,E14)) | L14: =COUNTIF(I14:K14,"X") | M14: =IF(OR(G14="",L14=0),0,G14/L14)
B15: =IF(A15="","",IF(A15<DataPartenza,"pre",MAX(1,A15-DataPartenza))) | G15: =IF(E15="","",IF(UPPER(F15)="JPY",E15/Tasso_JPY_EUR,E15)) | L15: =COUNTIF(I15:K15,"X") | M15: =IF(OR(G15="",L15=0),0,G15/L15)
B16: =IF(A16="","",IF(A16<DataPartenza,"pre",MAX(1,A16-DataPartenza))) | G16: =IF(E16="","",IF(UPPER(F16)="JPY",E16/Tasso_JPY_EUR,E16)) | L16: =COUNTIF(I16:K16,"X") | M16: =IF(OR(G16="",L16=0),0,G16/L16)
B17: =IF(A17="","",IF(A17<DataPartenza,"pre",MAX(1,A17-DataPartenza))) | G17: =IF(E17="","",IF(UPPER(F17)="JPY",E17/Tasso_JPY_EUR,E17)) | L17: =COUNTIF(I17:K17,"X") | M17: =IF(OR(G17="",L17=0),0,G17/L17)
B18: =IF(A18="","",IF(A18<DataPartenza,"pre",MAX(1,A18-DataPartenza))) | G18: =IF(E18="","",IF(UPPER(F18)="JPY",E18/Tasso_JPY_EUR,E18)) | L18: =COUNTIF(I18:K18,"X") | M18: =IF(OR(G18="",L18=0),0,G18/L18)
B19: =IF(A19="","",IF(A19<DataPartenza,"pre",MAX(1,A19-DataPartenza))) | G19: =IF(E19="","",IF(UPPER(F19)="JPY",E19/Tasso_JPY_EUR,E19)) | L19: =COUNTIF(I19:K19,"X") | M19: =IF(OR(G19="",L19=0),0,G19/L19)
B20: =IF(A20="","",IF(A20<DataPartenza,"pre",MAX(1,A20-DataPartenza))) | G20: =IF(E20="","",IF(UPPER(F20)="JPY",E20/Tasso_JPY_EUR,E20)) | L20: =COUNTIF(I20:K20,"X") | M20: =IF(OR(G20="",L20=0),0,G20/L20)
B21: =IF(A21="","",IF(A21<DataPartenza,"pre",MAX(1,A21-DataPartenza))) | G21: =IF(E21="","",IF(UPPER(F21)="JPY",E21/Tasso_JPY_EUR,E21)) | L21: =COUNTIF(I21:K21,"X") | M21: =IF(OR(G21="",L21=0),0,G21/L21)
B22: =IF(A22="","",IF(A22<DataPartenza,"pre",MAX(1,A22-DataPartenza))) | G22: =IF(E22="","",IF(UPPER(F22)="JPY",E22/Tasso_JPY_EUR,E22)) | L22: =COUNTIF(I22:K22,"X") | M22: =IF(OR(G22="",L22=0),0,G22/L22)
B23: =IF(A23="","",IF(A23<DataPartenza,"pre",MAX(1,A23-DataPartenza))) | G23: =IF(E23="","",IF(UPPER(F23)="JPY",E23/Tasso_JPY_EUR,E23)) | L23: =COUNTIF(I23:K23,"X") | M23: =IF(OR(G23="",L23=0),0,G23/L23)
B24: =IF(A24="","",IF(A24<DataPartenza,"pre",MAX(1,A24-DataPartenza))) | G24: =IF(E24="","",IF(UPPER(F24)="JPY",E24/Tasso_JPY_EUR,E24)) | L24: =COUNTIF(I24:K24,"X") | M24: =IF(OR(G24="",L24=0),0,G24/L24)
... B124: =IF(A124="","",IF(A124<DataPartenza,"pre",MAX(1,A124-DataPartenza))) | G124: =IF(E124="","",IF(UPPER(F124)="JPY",E124/Tasso_JPY_EUR,E124)) | L124: =COUNTIF(I124:K124,"X") | M124: =IF(OR(G124="",L124=0),0,G124/L124)
D125: TOTALE SPESO (gruppo) | G125: =SUM(G5:G124)

Sheet BUDGET
A1: BUDGET — Stimato vs Reale
A2: Il budget stimato arriva dal CONFIG; lo speso reale è calcolato dal registro SPESE (SUMIF per categoria).
A4: Categoria | B4: Budget gruppo € | C4: Budget/pax € | D4: Speso gruppo € | E4: Speso/pax € | F4: Delta € | G4: Utilizzo | H4: Note
A5: Voli | B5: =BudgetVoli*N_Persone | C5: =BudgetVoli | D5: =SUMIF(Spese_Categoria,A5,Spese_ImportoTot) | E5: =IF(D5=0,0,D5/N_Persone) | F5: =B5-D5 | G5: =IF(B5=0,"",D5/B5) | H5: China Eastern open-jaw (reale)
A6: Alloggio | B6: =BudgetAlloggio*N_Persone | C6: =BudgetAlloggio | D6: =SUMIF(Spese_Categoria,A6,Spese_ImportoTot) | E6: =IF(D6=0,0,D6/N_Persone) | F6: =B6-D6 | G6: =IF(B6=0,"",D6/B6) | H6: 4 strutture · 13 notti (reale)
A7: Trasporti | B7: =BudgetTrasporti*N_Persone | C7: =BudgetTrasporti | D7: =SUMIF(Spese_Categoria,A7,Spese_ImportoTot) | E7: =IF(D7=0,0,D7/N_Persone) | F7: =B7-D7 | G7: =IF(B7=0,"",D7/B7) | H7: JR pass + Kyoto→Tokyo + locali
A8: Ingressi/Attività | B8: =BudgetIngressi*N_Persone | C8: =BudgetIngressi | D8: =SUMIF(Spese_Categoria,A8,Spese_ImportoTot) | E8: =IF(D8=0,0,D8/N_Persone) | F8: =B8-D8 | G8: =IF(B8=0,"",D8/B8) | H8: USJ, Sanrio, torri, templi…
A9: Cibo | B9: =BudgetCibo*N_Persone | C9: =BudgetCibo | D9: =SUMIF(Spese_Categoria,A9,Spese_ImportoTot) | E9: =IF(D9=0,0,D9/N_Persone) | F9: =B9-D9 | G9: =IF(B9=0,"",D9/B9) | H9: Rebecca cucina: possibile risparmio
A10: Spese personali | B10: =BudgetPersonali*N_Persone | C10: =BudgetPersonali | D10: =SUMIF(Spese_Categoria,A10,Spese_ImportoTot) | E10: =IF(D10=0,0,D10/N_Persone) | F10: =B10-D10 | G10: =IF(B10=0,"",D10/B10) | H10: Souvenir ed extra
A11: Souvenir | B11: =BudgetSouvenir*N_Persone | C11: =BudgetSouvenir | D11: =SUMIF(Spese_Categoria,A11,Spese_ImportoTot) | E11: =IF(D11=0,0,D11/N_Persone) | F11: =B11-D11 | G11: =IF(B11=0,"",D11/B11) | H11: Voce libera
A12: Assicurazione | B12: =BudgetAssicurazione*N_Persone | C12: =BudgetAssicurazione | D12: =SUMIF(Spese_Categoria,A12,Spese_ImportoTot) | E12: =IF(D12=0,0,D12/N_Persone) | F12: =B12-D12 | G12: =IF(B12=0,"",D12/B12) | H12: Provider da annotare
A13: eSIM | B13: =BudgetESIM*N_Persone | C13: =BudgetESIM | D13: =SUMIF(Spese_Categoria,A13,Spese_ImportoTot) | E13: =IF(D13=0,0,D13/N_Persone) | F13: =B13-D13 | G13: =IF(B13=0,"",D13/B13) | H13: Klook / Airalo
A14: Bagagli | B14: =BudgetBagagli*N_Persone | C14: =BudgetBagagli | D14: =SUMIF(Spese_Categoria,A14,Spese_ImportoTot) | E14: =IF(D14=0,0,D14/N_Persone) | F14: =B14-D14 | G14: =IF(B14=0,"",D14/B14) | H14: Takkyubin Osaka→Tokyo
A15: Extra | B15: =BudgetExtra*N_Persone | C15: =BudgetExtra | D15: =SUMIF(Spese_Categoria,A15,Spese_ImportoTot) | E15: =IF(D15=0,0,D15/N_Persone) | F15: =B15-D15 | G15: =IF(B15=0,"",D15/B15) | H15: Imprevisti
A16: TOTALE | B16: =SUM(B5:B15) | C16: =SUM(C5:C15) | D16: =SUM(D5:D15) | E16: =SUM(E5:E15) | F16: =SUM(F5:F15) | G16: =IF(B16=0,"",D16/B16)

Sheet SCADENZE
A1: SCADENZE — Timeline prenotazioni
A2: Ordinate per data. 'Giorni' e 'Stato' si calcolano da TODAY(): rosso = urgente/scaduta.
A4: Data | B4: Cosa | C4: Categoria | D4: Priorità | E4: Giorni | F4: Stato | G4: Note
A5: 46293 | B5: Acquisto JR Kansai-Hiroshima Pass + posti Shinkansen A/R | C5: Trasporti | D5: Alta | E5: =IF(A5="","",A5-TODAY()) | F5: =IF(A5="","",IF(A5-TODAY()<0,"Scaduta",IF(A5-TODAY()<=7,"Urgente",IF(A5-TODAY()<=30,"In arrivo","Programmata")))) | G5: 28 set 10:00 JST · JR-WEST ONLINE · in Italia ~03:00
A6: 46296 | B6: Prenotazione Kyoto→Tokyo Hikari (SmartEX) | C6: Trasporti | D6: Alta | E6: =IF(A6="","",A6-TODAY()) | F6: =IF(A6="","",IF(A6-TODAY()<0,"Scaduta",IF(A6-TODAY()<=7,"Urgente",IF(A6-TODAY()<=30,"In arrivo","Programmata")))) | G6: 1 ott 10:00 JST · posto riservato ~¥13.650
A7: 46297 | B7: Prenotazione Tokyo Skytree (1 nov) | C7: Attività | D7: Media | E7: =IF(A7="","",A7-TODAY()) | F7: =IF(A7="","",IF(A7-TODAY()<0,"Scaduta",IF(A7-TODAY()<=7,"Urgente",IF(A7-TODAY()<=30,"In arrivo","Programmata")))) | G7: ~30 gg prima, 00:00 JST
A8: 46306 | B8: Scadenza sconto Hayatoku 21 (Kyoto→Tokyo) | C8: Trasporti | D8: Media | E8: =IF(A8="","",A8-TODAY()) | F8: =IF(A8="","",IF(A8-TODAY()<0,"Scaduta",IF(A8-TODAY()<=7,"Urgente",IF(A8-TODAY()<=30,"In arrivo","Programmata")))) | G8: Entro l'11 ott per lo sconto
A9: 46309 | B9: Comprare eSIM Giappone | C9: eSIM | D9: Alta | E9: =IF(A9="","",A9-TODAY()) | F9: =IF(A9="","",IF(A9-TODAY()<0,"Scaduta",IF(A9-TODAY()<=7,"Urgente",IF(A9-TODAY()<=30,"In arrivo","Programmata")))) | G9: ~2 settimane prima (Klook/Airalo)
A10: 46316 | B10: Prenotazione Shibuya Sky (4 nov, tramonto) ⭐Rebecca | C10: Attività | D10: Alta | E10: =IF(A10="","",A10-TODAY()) | F10: =IF(A10="","",IF(A10-TODAY()<0,"Scaduta",IF(A10-TODAY()<=7,"Urgente",IF(A10-TODAY()<=30,"In arrivo","Programmata")))) | G10: 21 ott 00:00 JST · finestra 14 gg · ¥3.400
A11: 46318 | B11: PARTENZA — Volo MU788 FCO→PVG 21:10 | C11: Viaggio | D11: Alta | E11: =IF(A11="","",A11-TODAY()) | F11: =IF(A11="","",IF(A11-TODAY()<0,"Scaduta",IF(A11-TODAY()<=7,"Urgente",IF(A11-TODAY()<=30,"In arrivo","Programmata")))) | G11: Check-in FCO ~18:10
A12: 46322 | B12: Verifica maree Miyajima | C12: Info | D12: Media | E12: =IF(A12="","",A12-TODAY()) | F12: =IF(A12="","",IF(A12-TODAY()<0,"Scaduta",IF(A12-TODAY()<=7,"Urgente",IF(A12-TODAY()<=30,"In arrivo","Programmata")))) | G12: Giorno prima di Hiroshima · tassa 100 ¥
A13: 46323 | B13: Attivazione JR Pass + Hiroshima/Miyajima | C13: Viaggio | D13: Alta | E13: =IF(A13="","",A13-TODAY()) | F13: =IF(A13="","",IF(A13-TODAY()<0,"Scaduta",IF(A13-TODAY()<=7,"Urgente",IF(A13-TODAY()<=30,"In arrivo","Programmata")))) | G13: Sveglia 05:15 · ritirare pass
A14: 46324 | B14: Takkyubin valigie Osaka→Tokyo (consegna 1 nov) | C14: Bagagli | D14: Alta | E14: =IF(A14="","",A14-TODAY()) | F14: =IF(A14="","",IF(A14-TODAY()<0,"Scaduta",IF(A14-TODAY()<=7,"Urgente",IF(A14-TODAY()<=30,"In arrivo","Programmata")))) | G14: Yamato Namba Station Center 9:00–20:00
A15: 46327 | B15: Consegna bagagli a Tokyo + Kyoto→Tokyo | C15: Viaggio | D15: Alta | E15: =IF(A15="","",A15-TODAY()) | F15: =IF(A15="","",IF(A15-TODAY()<0,"Scaduta",IF(A15-TODAY()<=7,"Urgente",IF(A15-TODAY()<=30,"In arrivo","Programmata")))) | G15: Arrivo Tokyo · Skytree
A16: 46329 | B16: Sanrio Puroland | C16: Attività | D16: Media | E16: =IF(A16="","",A16-TODAY()) | F16: =IF(A16="","",IF(A16-TODAY()<0,"Scaduta",IF(A16-TODAY()<=7,"Urgente",IF(A16-TODAY()<=30,"In arrivo","Programmata")))) | G16: Bunka no Hi · arrivare presto
... A19: 46332 | B19: RITORNO — Volo MU576 HND→PVG 08:40 | C19: Viaggio | D19: Alta | E19: =IF(A19="","",A19-TODAY()) | F19: =IF(A19="","",IF(A19-TODAY()<0,"Scaduta",IF(A19-TODAY()<=7,"Urgente",IF(A19-TODAY()<=30,"In arrivo","Programmata")))) | G19: Sveglia 04:30 · arrivo FCO 18:15

Sheet SALDI
A1: SALDI — Chi ha anticipato e chi deve dare
A2: Anticipato = spese pagate dalla persona. Quota = spese in cui è spuntata con 'X'. Saldo = Anticipato - Quota.
A4: Persona | B4: Anticipato € | C4: Quota dovuta € | D4: Saldo € | E4: Stato | F4: Note
A5: =CONFIG!$B$15 | B5: =SUMIF(Spese_PagatoDa,A5,Spese_ImportoTot) | C5: =SUMIFS(Spese_QuotaPax,Spese_P1,"X",Spese_PagatoDa,"<>") | D5: =B5-C5 | E5: =IF(AND(B5=0,C5=0),"",IF(D5>0.01,"Da ricevere",IF(D5<-0.01,"Da pagare","In pari"))) | F5: Chi ha speso di più riceve dagli altri
A6: =CONFIG!$B$16 | B6: =SUMIF(Spese_PagatoDa,A6,Spese_ImportoTot) | C6: =SUMIFS(Spese_QuotaPax,Spese_P2,"X",Spese_PagatoDa,"<>") | D6: =B6-C6 | E6: =IF(AND(B6=0,C6=0),"",IF(D6>0.01,"Da ricevere",IF(D6<-0.01,"Da pagare","In pari"))) | F6: Spunta le persone in SPESE (colonne 'X')
A7: =CONFIG!$B$17 | B7: =SUMIF(Spese_PagatoDa,A7,Spese_ImportoTot) | C7: =SUMIFS(Spese_QuotaPax,Spese_P3,"X",Spese_PagatoDa,"<>") | D7: =B7-C7 | E7: =IF(AND(B7=0,C7=0),"",IF(D7>0.01,"Da ricevere",IF(D7<-0.01,"Da pagare","In pari"))) | F7: Compila 'Pagato da' per calcolare i saldi
A8: TOTALE | B8: =SUM(B5:B7) | C8: =SUM(C5:C7) | D8: =SUM(D5:D7)
A9: Senza 'Pagato da' | B9: =SUMIF(Spese_PagatoDa,"",Spese_ImportoTot) | C9: =IF(B9>0,"⚠ assegna chi ha pagato per calcolare i saldi","tutto assegnato")
A10: Stile Tricount: in SPESE scegli chi ha pagato e spunta con 'X' chi divide la spesa (una, due o tutte le persone). La quota/persona è sempre importo totale ÷ partecipanti. I saldi contano solo le spese con 'Pagato da' compilato: saldo positivo = deve RICEVERE, saldo negativo = deve PAGARE.

Sheet LOGISTICA
A1: LOGISTICA — Info rapide
A2: Voli, alloggi, trasporti, emergenze, allergie Rebecca. Riferimenti utili sul campo.
A4: VOLI — China Eastern (prenotati 09/08/26)
A5: Tratta | B5: Percorso | C5: Orari | D5: Voli | E5: Durata
A6: Andata | B6: FCO→KIX | C6: 23 ott 21:10 → 24 ott 21:00 | D6: MU788 + FM3051 (via Shanghai PVG) | E6: 16h50
A7: Ritorno | B7: HND→FCO | C7: 6 nov 08:40 → 18:15 | D7: MU576 + MU787 (via Shanghai PVG) | E7: 17h35
A9: ALLOGGI — tutti prenotati (cucina per Rebecca)
A10: Città | B10: Struttura | C10: Date | D10: Notti | E10: Indirizzo
A11: Izumisano (KIX) | B11: KURA Hotel Izumisano | C11: 24–25 ott | D11: 1 | E11: Uemachi 3-10-11, Izumisano | F11: 16:00 / 10:00 · Kitchenette + microonde
A12: Osaka | B12: Hanazonocho Apartment 103 | C12: 25–29 ott | D12: 4 | E12: 1-2-35 Bainan, Nishinari Ward | F12: 16:00 / 10:00 · Angolo cottura
A13: Kyoto | B13: Miro Kyoto Nijo Hotel | C13: 29 ott–1 nov | D13: 3 | E13: 20-1 Nishinokyokangakuincho, Nakagyo | F13: 16:00 / 10:00 · Cucina attrezzata
A14: Tokyo | B14: Taito City Guesthouse | C14: 1–6 nov | D14: 5 | E14: 4-27-6 Senzoku, Taito City | F14: 15:00 / 10:00 · Cucina condivisa (1° piano)
A17: TRASPORTI — Pass & biglietti
A18: Voce | B18: Copertura | C18: Costo | D18: Quando | E18: Note
A19: JR Kansai-Hiroshima Area Pass (5gg) | B19: Shinkansen Shin-Osaka⇔Hiroshima A/R, traghetto JR Miyajima, linee JR West | C19: 17.000 ¥ (~92 €) | D19: Attivo 28 ott – 1 nov | E19: Acquistare su JR-WEST ONLINE (posti online dal 28/09)
A20: Kyoto→Tokyo Shinkansen Hikari | B20: Posto riservato, ~2h40 | C20: ~13.650 ¥ (~74 €) | D20: 1 nov | E20: SmartEX · Hayatoku 21 entro 11/10
A21: Suica / Icoca | B21: Metro, bus, treni locali, konbini | C21: Ricarica | D21: Tutto il viaggio | E21: Suica digitale su iPhone o Icoca a KIX
A22: Osaka→Nara (Kintetsu) | B22: Non coperto dal JR Pass | C22: ~570 ¥ | D22: 29 ott | E22: IC card
A23: Nara→Kyoto (JR Nara Line) | B23: Incluso nel pass | C23: — | D23: 29 ott | E23: —
A25: EMERGENZE & ASSISTENZA
A26: Numero | B26: Servizio | C26: Note
A27: 110 | B27: Polizia | C27: Gratuito da qualsiasi telefono
A28: 119 | B28: Ambulanza / Vigili del Fuoco | C28: Gratuito da qualsiasi telefono
A29: 118 | B29: Guardia Costiera | C29: Emergenze in mare
A30: #7119 | B30: Consulenza medica urgente 24h | C30: Operatori in inglese
A31: +81-3-3501-0110 | B31: Ambasciata d'Italia a Tokyo | C31: 2-11-3 Mita, Meguro-ku
A32: +81-6-6226-3100 | B32: Consolato onorario Osaka | C32: —
A33: Assicurazione | B33: Heymondo — n. polizza e provider da annotare · app con chat medica 24/7
A35: ⚠️ ALLERGIE REBECCA — CRITICO
A36: • SOIA (shoyu, miso, tofu, edamame, natto, dashi) — ONNIPRESENTE
A37: • PESCE (dashi, bonito, sushi) · CROSTACEI · FRUTTA SECCA
A38: • BANANA · FRAGOLA · KIWI · ARANCIA · NICHEL (lieve: pomodoro, spinaci, cipolla)
A39: • Rebecca deve cucinare da sola: TUTTI gli alloggi hanno cucina.
A40: • Sicuri: Saizeriya (pasta aglio e olio), Matsuya (gyudon senza salsa), Sukiya (riso+uovo), yakiniku (carne non marinata, sale/limone), Royal Host, Shogun Burger.
A41: Portare SEMPRE il cartellino allergie in giapponese (plastificato).
A43: Riferimenti nel vault: Lista Prenotazioni · Spese Reali · Allergie Alimentari Rebecca · Info pratiche · Attività e Prenotazioni · Trasferimento Bagagli (Takkyubin).

Sheet CONFIG
A1: CONFIG — Fonte unica di verita'
A2: Modifica SOLO questo foglio: date, tasso, persone, liste e budget alimentano tutte le formule del workbook.
A4: VIAGGIO
A5: Nome viaggio | B5: Giappone 2026 — 23 Ott / 6 Nov
A6: Data partenza | B6: 46318
A7: Data ritorno | B7: 46332
A8: Ultimo giorno (rientro) | B8: 46333
A9: N° persone | B9: =COUNTA(B15:B19)
A10: Tasso di cambio (1 € = ? ¥) | B10: 184
A11: Budget target / persona (€) | B11: 2875
A12: Valuta base | B12: EUR
A14: PERSONE
A15: Persona 1 | B15: Lorenzo
A16: Persona 2 | B16: Davide
A17: Persona 3 | B17: Rebecca
A18: Persona 4
A19: Persona 5
A34: BUDGET PER CATEGORIA (€ / persona)
A35: Categoria | B35: Budget €/persona
A36: Voli | B36: 1096.33
A37: Alloggio | B37: 359.89
A38: Trasporti | B38: 302.57
A39: Ingressi/Attività | B39: 206
A40: Cibo | B40: 420
A41: Spese personali | B41: 400
A42: Souvenir | B42: 0
A43: Assicurazione | B43: 53.43
A44: eSIM | B44: 20
A45: Bagagli | B45: 17.17
A46: Extra | B46: 0
A47: TOTALE | B47: =SUM(B36:B46)
A50: COME SI USA
A51: Regola d'oro | B51: Modifica solo CONFIG (date, tasso, persone, liste, budget) e il registro SPESE. Tutto il resto e' formula: si ricalcola da solo.
A52: Aggiungere una spesa | B52: SPESE: compila Data, Categoria, Descrizione, Importo TOTALE, Valuta, poi scegli 'Pagato da'. Importo €, quota/persona e saldi si calcolano.
A53: Dividere una spesa | B53: Stile Tricount: spunta con 'X' le colonne delle persone che dividono la spesa (una, due o tutte). La quota/persona è sempre importo totale ÷ numero di spuntati.
A54: Prenotazioni | B54: PRENOTAZIONI e' solo per logistica e scadenze (canale, costo, stato, codice conferma). Chi ha pagato e come si divide si registra in SPESE.
A55: Attività | B55: ATTIVITÀ: aggiorna lo Stato (Da fare / Fatto / Saltato / Opzionale). ITINERARIO mostra automaticamente quante attività per giorno sono state fatte.
A56: Saldi | B56: SALDI conta solo le spese con 'Pagato da' compilato: saldo positivo = deve ricevere, negativo = deve pagare. Le spese senza pagante sono mostrate a parte.
A57: Estendere | B57: Aggiungi voci in fondo alle liste del CONFIG: i menu a tendina si allargano da soli (range dinamici). I fogli SPESE/PRENOTAZIONI hanno righe con formule gia' pronte.
A58: Rigenerare | B58: python _website/scripts/generate-companion-workbook.py — ricrea il file dai dati sorgente.
...
